Workbook

Sheet Import
A1: Row Labels | B1: Count | C1: Min | D1: Mean | E1: Max | F1: SD | G1: 25th | H1: Median | I1: 75th | J1: Measure | K1: Geography

Sheet ImpM1
A1: Row Labels | B1: Count | C1: Min | D1: Mean | E1: Max | F1: SD | G1: 25th | H1: Median | I1: 75th | J1: Measure | K1: Geography
A2: Raleigh, NC | B2: 8 | C2: 13.778899 | D2: 20.165824 | E2: 31.490593 | F2: 7.0688265 | G2: 14.305861 | H2: 18.738663 | I2: 27.747505 | J2: Measure 1 | K2: MSA
A3: Durham-Chapel Hill, NC | B3: 8 | C3: 13.238334 | D3: 22.2275 | E3: 42.766579 | F3: 11.161205 | G3: 14.320551 | H3: 17.40989 | I3: 32.648028 | J3: Measure 1 | K3: MSA
A4: Lexington-Fayette, KY | B4: 8 | C4: 17.527112 | D4: 28.571308 | E4: 50.165113 | F4: 9.7344 | G4: 22.351848 | H4: 27.822132 | I4: 29.967448 | J4: Measure 1 | K4: MSA
A5: BANGKOK | B5: 8 | C5: 30.862357 | D5: 68.763303 | E5: 169.7506 | F5: 44.464407 | G5: 40.0885 | H5: 59.150143 | I5: 81.512115 | J5: Measure 1 | K5: MSA
A6: Wichita, KS | B6: 8 | C6: 30.533045 | D6: 59.835064 | E6: 98.509396 | F6: 27.916419 | G6: 31.839221 | H6: 57.713192 | I6: 86.809668 | J6: Measure 1 | K6: MSA
A7: ISTANBUL | B7: 8 | C7: 20.838434 | D7: 56.9397 | E7: 114.8845 | F7: 31.174614 | G7: 29.82375 | H7: 51.320829 | I7: 79.232903 | J7: Measure 1 | K7: MSA
A8: JAVA ISLAND INDONESIA | B8: 9 | C8: 64.36895 | D8: 119.93519 | E8: 207.88061 | F8: 46.431164 | G8: 86.694412 | H8: 110.13222 | I8: 153.68123 | J8: Measure 1 | K8: MSA
A9: Memphis, TN-MS-AR | B9: 9 | C9: 20.909394 | D9: 27.945041 | E9: 34.261497 | F9: 4.7470075 | G9: 23.458469 | H9: 28.032939 | I9: 32.294369 | J9: Measure 1 | K9: MSA
A10: Sacramento--Roseville--Arden-Arcade, CA | B10: 9 | C10: 8.0834548 | D10: 26.848936 | E10: 142.06653 | F10: 43.314601 | G10: 9.5984079 | H10: 14.997115 | I10: 15.792013 | J10: Measure 1 | K10: MSA
A11: Oklahoma City, OK | B11: 9 | C11: 21.054188 | D11: 35.252699 | E11: 75.058929 | F11: 17.53638 | G11: 23.874648 | H11: 30.275658 | I11: 42.74457 | J11: Measure 1 | K11: MSA
A12: Colorado Springs, CO | B12: 10 | C12: 23.105297 | D12: 32.590867 | E12: 47.165436 | F12: 7.1539837 | G12: 25.937956 | H12: 32.807304 | I12: 37.40757 | J12: Measure 1 | K12: MSA
A13: Knoxville, TN | B13: 10 | C13: 17.558453 | D13: 59.729473 | E13: 237.71626 | F13: 67.632094 | G13: 21.341635 | H13: 25.892518 | I13: 82.043779 | J13: Measure 1 | K13: MSA
... A69: Washington-Arlington-Alexandria, DC-VA-MD-WV | B69: 93 | C69: 1.338267 | D69: 40.40864 | E69: 212.84195 | F69: 38.808433 | G69: 21.056344 | H69: 26.356976 | I69: 40.089969 | J69: Measure 1 | K69: MSA
A70: Grand Total | B70: 1656 | C70: 1.338267 | D70: 39.36871 | E70: 237.71626 | F70: 37.746306 | G70: #NUM! | H70: #NUM! | I70: #NUM! | J70: #NUM! | K70: MSA
A151: AUSTRIA | B151: 8 | C151: 5.712821 | D151: 17.647432 | E151: 38.629287 | F151: 10.45871 | G151: 11.160598 | H151: 14.025346 | I151: 24.323345 | J151: Measure 1 | K151: Country
A152: SPAIN | B152: 8 | C152: 10.72809 | D152: 45.031965 | E152: 100.97556 | F152: 28.019397 | G152: 20.741425 | H152: 46.214395 | I152: 56.818018 | J152: Measure 1 | K152: Country
A153: SWITZERLAND | B153: 8 | C153: 0.87078977 | D153: 9.3217575 | E153: 36.897869 | F153: 11.630453 | G153: 3.0220543 | H153: 5.9199211 | I153: 10.563425 | J153: Measure 1 | K153: Country
A154: JORDAN | B154: 9 | C154: 39.584905 | D154: 199.07367 | E154: 363.85934 | F154: 121.96646 | G154: 77.908461 | H154: 234.03836 | I154: 297.34126 | J154: Measure 1 | K154: Country
A155: KOREA | B155: 10 | C155: 33.999072 | D155: 67.937011 | E155: 98.084938 | F155: 22.983352 | G155: 49.6195 | H155: 70.267612 | I155: 87.132639 | J155: Measure 1 | K155: Country
A156: TURKEY | B156: 10 | C156: 20.838434 | D156: 67.33827 | E156: 114.8845 | F156: 35.208857 | G156: 35.607912 | H156: 62.201714 | I156: 107.03631 | J156: Measure 1 | K156: Country
A157: AUSTRALIA | B157: 12 | C157: 20.991575 | D157: 53.787433 | E157: 115.28802 | F157: 26.788816 | G157: 31.487394 | H157: 50.62733 | I157: 64.146429 | J157: Measure 1 | K157: Country
A158: INDONESIA | B158: 14 | C158: 55.226441 | D158: 126.64183 | E158: 412.04663 | F158: 92.884607 | G158: 74.337541 | H158: 93.556831 | I158: 141.81593 | J158: Measure 1 | K158: Country
A159: HONG KONG | B159: 14 | C159: 33.596161 | D159: 93.50692 | E159: 233.57118 | F159: 62.283428 | G159: 45.120803 | H159: 73.213284 | I159: 127.13725 | J159: Measure 1 | K159: Country
A160: RUSSIAN FEDERATION | B160: 14 | C160: 22.079245 | D160: 50.993481 | E160: 90.283135 | F160: 18.566785 | G160: 36.603492 | H160: 43.988529 | I160: 66.307112 | J160: Measure 1 | K160: Country
A161: SAUDI ARABIA | B161: 16 | C161: 15.431246 | D161: 180.8321 | E161: 446.89651 | F161: 103.6329 | G161: 115.5941 | H161: 161.22578 | I161: 187.64314 | J161: Measure 1 | K161: Country
A162: THAILAND | B162: 16 | C162: 30.862357 | D162: 78.148996 | E162: 258.34944 | F162: 58.825051 | G162: 41.045069 | H162: 60.413608 | I162: 85.597606 | J162: Measure 1 | K162: Country
... A172: UNITED STATES | B172: 2109 | C172: 1.338267 | D172: 36.364688 | E172: 237.71626 | F172: 34.575687 | G172: 18.256159 | H172: 24.215695 | I172: 37.632097 | J172: Measure 1 | K172: Country
A173: Grand Total | B173: 2686 | C173: 0.87078977 | D173: 42.071911 | E173: 446.89651 | F173: 42.901742 | G173: #NUM! | H173: #NUM! | I173: #NUM! | J173: #NUM! | K173: Country
A301: MONTREAL MSA | B301: 8 | C301: 0.96910936 | D301: 7.2454047 | E301: 18.606987 | F301: 5.9089049 | G301: 3.3292742 | H301: 5.3284337 | I301: 11.875546 | J301: Measure 1 | K301: Region
A302: BAJIO-CENTRAL MEXICO | B302: 8 | C302: 16.212694 | D302: 46.301658 | E302: 73.271706 | F302: 20.435633 | G302: 25.978405 | H302: 48.582714 | I302: 63.79384 | J302: Measure 1 | K302: Region
A303: JAVA ISLAND INDONESIA | B303: 9 | C303: 64.36895 | D303: 119.93519 | E303: 207.88061 | F303: 46.431164 | G303: 86.694412 | H303: 110.13222 | I303: 153.68123 | J303: Measure 1 | K303: Region
A304: GUANGDONG CHINA | B304: 10 | C304: 14.957218 | D304: 86.228413 | E304: 121.89933 | F304: 33.585688 | G304: 60.502752 | H304: 93.876102 | I304: 114.58393 | J304: Measure 1 | K304: Region
A305: MAHARASHTRA INDIA | B305: 10 | C305: 39.010815 | D305: 87.598426 | E305: 146.93973 | F305: 39.139971 | G305: 56.484858 | H305: 80.712004 | I305: 134.87465 | J305: Measure 1 | K305: Region
A306: BANGKOK 200KM | B306: 11 | C306: 30.862357 | D306: 69.276301 | E306: 169.7506 | F306: 39.763318 | G306: 40.382405 | H306: 59.511787 | I306: 87.614105 | J306: Measure 1 | K306: Region
A307: NORTHERN MEXICO | B307: 11 | C307: 23.76321 | D307: 64.424048 | E307: 128.93401 | F307: 33.122506 | G307: 37.551041 | H307: 56.314629 | I307: 90.778435 | J307: Measure 1 | K307: Region
A308: SOUTHERN GERMANY | B308: 15 | C308: 14.932337 | D308: 26.193396 | E308: 75.82373 | F308: 15.989477 | G308: 17.186961 | H308: 20.050291 | I308: 26.183088 | J308: Measure 1 | K308: Region
A309: CARIBBEAN | B309: 19 | C309: 15.86288 | D309: 83.935761 | E309: 348.18133 | F309: 89.995184 | G309: 34.374637 | H309: 53.773563 | I309: 75.030655 | J309: Measure 1 | K309: Region
A310: NORTHERN GERMANY | B310: 19 | C310: 9.4891844 | D310: 27.74144 | E310: 62.570587 | F310: 12.541738 | G310: 17.445645 | H310: 28.135438 | I310: 34.926098 | J310: Measure 1 | K310: Region
A311: Toronto 200KM | B311: 22 | C311: 7.6373095 | D311: 43.053237 | E311: 188.66638 | F311: 49.955456 | G311: 11.494623 | H311: 15.810304 | I311: 65.701283 | J311: Measure 1 | K311: Region
...

Sheet ImpM2
A1: Row Labels | B1: Count | C1: Min | D1: Mean | E1: Max | F1: SD | G1: 25th | H1: Median | I1: 75th | J1: Measure | K1: Geography
A2: Knoxville, TN | B2: 8 | C2: 4427.9551 | D2: 8464.8165 | E2: 19356.822 | F2: 5273.7711 | G2: 4887.6469 | H2: 6385.561 | I2: 12036.221 | J2: Measure 2 | K2: MSA
A3: Montgomery, AL | B3: 8 | C3: 2808.9666 | D3: 11348.947 | E3: 31056.268 | F3: 11796.68 | G3: 4508.9238 | H3: 5706.613 | I3: 23931.522 | J3: Measure 2 | K3: MSA
A4: Dayton, OH | B4: 8 | C4: 5190.978 | D4: 7285.923 | E4: 9016.8184 | F4: 1219.7567 | G4: 6608.1942 | H4: 7047.1216 | I4: 8442.0632 | J4: Measure 2 | K4: MSA
A5: Greensboro-High Point, NC | B5: 8 | C5: 2393.7651 | D5: 9719.1326 | E5: 37260.648 | F5: 11572.18 | G5: 3686.3964 | H5: 5037.3093 | I5: 11360.203 | J5: Measure 2 | K5: MSA
A6: Albany-Schenectady-Troy, NY | B6: 8 | C6: 2034.921 | D6: 4017.9957 | E6: 5902.8784 | F6: 1393.2501 | G6: 2788.8784 | H6: 3956.6626 | I6: 5441.7295 | J6: Measure 2 | K6: MSA
A7: BANGKOK | B7: 8 | C7: 8836.4893 | D7: 18578.765 | E7: 33702.102 | F7: 7855.3042 | G7: 12166.663 | H7: 17866.182 | I7: 23262.784 | J7: Measure 2 | K7: MSA
A8: MONTREAL | B8: 8 | C8: 275.35913 | D8: 2645.4709 | E8: 7736.4756 | F8: 2443.8256 | G8: 902.6564 | H8: 1728.9777 | I8: 3958.9541 | J8: Measure 2 | K8: MSA
A9: BIRMINGHAM | B9: 8 | C9: 2837.1172 | D9: 5876.1111 | E9: 10770.446 | F9: 2280.755 | G9: 4708.2494 | H9: 5569.1155 | I9: 6351.3193 | J9: Measure 2 | K9: MSA
A10: SAO PAULO | B10: 8 | C10: 364.79895 | D10: 6024.3496 | E10: 28704.895 | F10: 9330.5895 | G10: 1835.7336 | H10: 2596.1873 | I10: 5684.3112 | J10: Measure 2 | K10: MSA
A11: DOHA | B11: 8 | C11: 12928.779 | D11: 35199.817 | E11: 93737.062 | F11: 29709.337 | G11: 18222.885 | H11: 21721.285 | I11: 58643.461 | J11: Measure 2 | K11: MSA
A12: Albuquerque, NM | B12: 9 | C12: 3025.0203 | D12: 6884.7228 | E12: 13852.534 | F12: 3409.9722 | G12: 3878.3567 | H12: 6513.3657 | I12: 8829.9995 | J12: Measure 2 | K12: MSA
A13: Raleigh, NC | B13: 9 | C13: 3240.6887 | D13: 5851.8831 | E13: 8520.3633 | F13: 2015.5735 | G13: 4066.6569 | H13: 5494.9707 | I13: 8228.9722 | J13: Measure 2 | K13: MSA
... A76: Washington-Arlington-Alexandria, DC-VA-MD-WV | B76: 102 | C76: 3295.5532 | D76: 7906.6232 | E76: 25708.971 | F76: 3945.0397 | G76: 5324.9976 | H76: 6869.9382 | I76: 8931.2842 | J76: Measure 2 | K76: MSA
A77: Grand Total | B77: 1840 | C77: 275.35913 | D77: 8893.6383 | E77: 124755.16 | F77: 7994.2804 | G77: #NUM! | H77: #NUM! | I77: #NUM! | J77: #NUM! | K77: MSA
A151: EGYPT | B151: 8 | C151: 163.31155 | D151: 16362.788 | E151: 45735.934 | F151: 13420.273 | G151: 10419.638 | H151: 12430.122 | I151: 21013.086 | J151: Measure 2 | K151: Country
A152: SPAIN | B152: 8 | C152: 1563.4916 | D152: 10666.003 | E152: 23266.664 | F152: 6863.3159 | G152: 5398.3931 | H152: 10140.882 | I152: 15322.794 | J152: Measure 2 | K152: Country
A153: QATAR | B153: 9 | C153: 12928.779 | D153: 34530.483 | E153: 93737.062 | F153: 27862.989 | G153: 18297.849 | H153: 24747.795 | I153: 49507.762 | J153: Measure 2 | K153: Country
A154: TURKEY | B154: 9 | C154: 6423.1699 | D154: 17330.976 | E154: 31296.166 | F154: 7693.5125 | G154: 12188.662 | H154: 17450.703 | I154: 22789.423 | J154: Measure 2 | K154: Country
A155: MALAYSIA | B155: 10 | C155: 12688.566 | D155: 19991.52 | E155: 26029.391 | F155: 4130.7071 | G155: 16734.529 | H155: 20363.048 | I155: 23691.411 | J155: Measure 2 | K155: Country
A156: KOREA | B156: 10 | C156: 9421.5811 | D156: 20851.801 | E156: 29132.174 | F156: 7213.5426 | G156: 13248.206 | H156: 22462.668 | I156: 27149.094 | J156: Measure 2 | K156: Country
A157: BRAZIL | B157: 10 | C157: 364.79895 | D157: 5306.3031 | E157: 28704.895 | F157: 8366.8952 | G157: 1982.6812 | H157: 2434.1172 | I157: 4430.003 | J157: Measure 2 | K157: Country
A158: COSTA RICA | B158: 10 | C158: 857.61707 | D158: 2943.5292 | E158: 6452.9497 | F158: 1972.1686 | G158: 1230.2972 | H158: 2425.4403 | I158: 4492.349 | J158: Measure 2 | K158: Country
A159: SWITZERLAND | B159: 10 | C159: 202.79396 | D159: 2077.5909 | E159: 7225.4785 | F159: 2061.579 | G159: 743.18628 | H159: 1441.7656 | I159: 2646.0078 | J159: Measure 2 | K159: Country
A160: AUSTRIA | B160: 11 | C160: 1340.0262 | D160: 3667.3614 | E160: 7579.3496 | F160: 2085.3786 | G160: 1614.0499 | H160: 3224.1636 | I160: 5745.687 | J160: Measure 2 | K160: Country
A161: AUSTRALIA | B161: 12 | C161: 7149.5996 | D161: 16866.96 | E161: 37095.434 | F161: 8671.5751 | G161: 8948.6218 | H161: 16032.421 | I161: 22167.739 | J161: Measure 2 | K161: Country
A162: INDONESIA | B162: 13 | C162: 16363.013 | D162: 34339.12 | E162: 124755.16 | F162: 28758.881 | G162: 17921.318 | H162: 28536.977 | I162: 33492.379 | J162: Measure 2 | K162: Country
... A176: UNITED STATES | B176: 2299 | C176: 662.30627 | D176: 7887.8914 | E176: 105021.98 | F176: 5419.2467 | G176: 4785.3945 | H176: 6377.9517 | I176: 9088.7666 | J176: Measure 2 | K176: Country
A177: Grand Total | B177: 2996 | C177: 163.31155 | D177: 9476.078 | E177: 128911.91 | F177: 9183.6272 | G177: #NUM! | H177: #NUM! | I177: #NUM! | J177: #NUM! | K177: Country
A301: JAVA ISLAND INDONESIA | B301: 9 | C301: 16806.604 | D301: 40280.246 | E301: 124755.16 | F301: 33168.664 | G301: 21745.089 | H301: 30084.959 | I301: 42119.312 | J301: Measure 2 | K301: Region
A302: MONTREAL MSA | B302: 9 | C302: 275.35913 | D302: 2525.6953 | E302: 7736.4756 | F302: 2314.0579 | G302: 987.06866 | H302: 1681.6804 | I302: 3859.9199 | J302: Measure 2 | K302: Region
A303: BAJIO-CENTRAL MEXICO | B303: 10 | C303: 3767.7371 | D303: 10599.267 | E303: 22428.268 | F303: 5910.8155 | G303: 4883.8462 | H303: 10812.843 | I303: 14314.392 | J303: Measure 2 | K303: Region
A304: BANGKOK 200KM | B304: 10 | C304: 8836.4893 | D304: 19172.604 | E304: 33702.102 | F304: 7131.8448 | G304: 13332.996 | H304: 18916.759 | I304: 24000.673 | J304: Measure 2 | K304: Region
A305: MAHARASHTRA INDIA | B305: 10 | C305: 14962.816 | D305: 24542.893 | E305: 36721.098 | F305: 8009.7047 | G305: 18408.08 | H305: 22336.255 | I305: 34401.667 | J305: Measure 2 | K305: Region
A306: GUANGDONG CHINA | B306: 11 | C306: 4191.8779 | D306: 24200.728 | E306: 36833.254 | F306: 9673.0675 | G306: 17259.16 | H306: 28864.338 | I306: 32487.096 | J306: Measure 2 | K306: Region
A307: NORTHERN MEXICO | B307: 11 | C307: 5806.9346 | D307: 14754.191 | E307: 28327.438 | F307: 7832.5589 | G307: 9010.4248 | H307: 11819.359 | I307: 22234.229 | J307: Measure 2 | K307: Region
A308: SOUTHERN GERMANY | B308: 17 | C308: 3698.762 | D308: 7448.0069 | E308: 20806.691 | F308: 5153.2143 | G308: 4393.481 | H308: 5100.4907 | I308: 8378.0869 | J308: Measure 2 | K308: Region
A309: NORTHERN GERMANY | B309: 19 | C309: 1819.3043 | D309: 7247.2202 | E309: 14372.479 | F309: 3357.5026 | G309: 4032.4946 | H309: 7233.9067 | I309: 9537.4434 | J309: Measure 2 | K309: Region
A310: Toronto 200KM | B310: 22 | C310: 1320.1914 | D310: 5227.4251 | E310: 18207.588 | F310: 4084.9906 | G310: 3055.3725 | H310: 3658.3557 | I310: 6570.6495 | J310: Measure 2 | K310: Region
A311: CARIBBEAN | B311: 28 | C311: 4643.5903 | D311: 16183.683 | E311: 27034.104 | F311: 6416.812 | G311: 10599.275 | H311: 16740.197 | I311: 20816.39 | J311: Measure 2 | K311: Region
...

Sheet ImpM3
A1: Row Labels | B1: Count | C1: Min | D1: Mean | E1: Max | F1: SD | G1: 25th | H1: Median | I1: 75th | J1: Measure | K1: Geography
A2: Albany-Schenectady-Troy, NY | B2: 8 | C2: 9.6711121 | D2: 32.158567 | E2: 142.041 | F2: 44.641676 | G2: 13.000083 | H2: 16.812227 | I2: 22.898511 | J2: Measure 3 | K2: MSA
A3: BANGKOK | B3: 8 | C3: 28.366102 | D3: 71.530988 | E3: 174.27077 | F3: 47.417945 | G3: 38.212075 | H3: 59.869244 | I3: 93.654078 | J3: Measure 3 | K3: MSA
A4: Las Vegas-Henderson-Paradise, NV | B4: 8 | C4: 17.876278 | D4: 43.639667 | E4: 126.78345 | F4: 41.78758 | G4: 20.606648 | H4: 22.752518 | I4: 75.552588 | J4: Measure 3 | K4: MSA
A5: BIRMINGHAM | B5: 8 | C5: 10.972478 | D5: 22.544912 | E5: 36.832935 | F5: 7.3717709 | G5: 19.466098 | H5: 21.061406 | I5: 25.676723 | J5: Measure 3 | K5: MSA
A6: Wichita, KS | B6: 8 | C6: 30.627213 | D6: 64.131453 | E6: 117.27309 | F6: 31.544405 | G6: 32.858435 | H6: 64.704018 | I6: 86.809668 | J6: Measure 3 | K6: MSA
A7: ISTANBUL | B7: 8 | C7: 20.278116 | D7: 58.867055 | E7: 117.45306 | F7: 31.762247 | G7: 29.839921 | H7: 55.738848 | I7: 80.049677 | J7: Measure 3 | K7: MSA
A8: Raleigh, NC | B8: 9 | C8: 14.004221 | D8: 21.481147 | E8: 31.01515 | F8: 7.2901082 | G8: 14.519198 | H8: 18.927055 | I8: 30.602872 | J8: Measure 3 | K8: MSA
A9: JAVA ISLAND INDONESIA | B9: 9 | C9: 75.472031 | D9: 153.45258 | E9: 451.00995 | F9: 116.51485 | G9: 93.975594 | H9: 106.03356 | I9: 163.20823 | J9: Measure 3 | K9: MSA
A10: Durham-Chapel Hill, NC | B10: 9 | C10: 13.341059 | D10: 24.473633 | E10: 42.766586 | F10: 11.859801 | G10: 15.200601 | H10: 17.176575 | I10: 38.185129 | J10: Measure 3 | K10: MSA
A11: Oklahoma City, OK | B11: 9 | C11: 21.562618 | D11: 36.882014 | E11: 75.058929 | F11: 18.212937 | G11: 24.167533 | H11: 27.523325 | I11: 50.333334 | J11: Measure 3 | K11: MSA
A12: Lexington-Fayette, KY | B12: 9 | C12: 17.527109 | D12: 32.686326 | E12: 60.030914 | F12: 15.038011 | G12: 22.725008 | H12: 27.978815 | I12: 43.514305 | J12: Measure 3 | K12: MSA
A13: Providence-Warwick, RI-MA | B13: 10 | C13: 12.545132 | D13: 20.991122 | E13: 36.81229 | F13: 7.417368 | G13: 15.467175 | H13: 19.672171 | I13: 24.983085 | J13: Measure 3 | K13: MSA
... A72: Washington-Arlington-Alexandria, DC-VA-MD-WV | B72: 111 | C72: 13.475057 | D72: 43.038112 | E72: 212.84195 | F72: 42.330962 | G72: 20.380949 | H72: 27.293924 | I72: 45.478085 | J72: Measure 3 | K72: MSA
A73: Grand Total | B73: 1911 | C73: 3.1385496 | D73: 40.856856 | E73: 451.00995 | F73: 38.960597 | G73: #NUM! | H73: #NUM! | I73: #NUM! | J73: #NUM! | K73: MSA
A151: AUSTRIA | B151: 8 | C151: 6.7573252 | D151: 18.189296 | E151: 41.913834 | F151: 11.098182 | G151: 11.038242 | H151: 14.553896 | I151: 23.280281 | J151: Measure 3 | K151: Country
A152: SPAIN | B152: 8 | C152: 9.867465 | D152: 43.940688 | E152: 95.910957 | F152: 25.870412 | G152: 23.337041 | H152: 44.27355 | I152: 53.334579 | J152: Measure 3 | K152: Country
A153: ITALY | B153: 8 | C153: 22.981277 | D153: 89.695925 | E153: 148.84778 | F153: 43.416027 | G153: 49.002144 | H153: 92.962437 | I153: 128.54476 | J153: Measure 3 | K153: Country
A154: SWITZERLAND | B154: 8 | C154: 0.79162705 | D154: 9.4636462 | E154: 36.404587 | F154: 11.450006 | G154: 3.1651623 | H154: 5.7007508 | I154: 11.329418 | J154: Measure 3 | K154: Country
A155: JORDAN | B155: 9 | C155: 41.98399 | D155: 197.29257 | E155: 338.76007 | F155: 116.3101 | G155: 83.653198 | H155: 215.61134 | I155: 309.92297 | J155: Measure 3 | K155: Country
A156: BRAZIL | B156: 9 | C156: 1.9587466 | D156: 22.67026 | E156: 111.25043 | F156: 33.86687 | G156: 7.7003973 | H156: 12.453773 | I156: 20.289699 | J156: Measure 3 | K156: Country
A157: KOREA | B157: 10 | C157: 31.284716 | D157: 71.997958 | E157: 101.26678 | F157: 24.459858 | G157: 54.719781 | H157: 74.493198 | I157: 93.413717 | J157: Measure 3 | K157: Country
A158: COSTA RICA | B158: 10 | C158: 3.7378438 | D158: 12.77884 | E158: 27.488459 | F158: 8.3826958 | G158: 7.0010558 | H158: 9.9277925 | I158: 19.080275 | J158: Measure 3 | K158: Country
A159: TURKEY | B159: 10 | C159: 20.278116 | D159: 71.879361 | E159: 127.69708 | F159: 39.247207 | G159: 38.309316 | H159: 64.609798 | I159: 118.12982 | J159: Measure 3 | K159: Country
A160: AUSTRALIA | B160: 12 | C160: 22.885714 | D160: 58.472826 | E160: 123.96136 | F160: 31.027695 | G160: 31.118021 | H160: 51.044691 | I160: 83.197226 | J160: Measure 3 | K160: Country
A161: HONG KONG | B161: 14 | C161: 30.541965 | D161: 93.029877 | E161: 246.32672 | F161: 63.490668 | G161: 43.015572 | H161: 74.364582 | I161: 120.56241 | J161: Measure 3 | K161: Country
A162: INDONESIA | B162: 14 | C162: 59.410263 | D162: 151.55074 | E162: 451.00995 | F162: 119.14536 | G162: 86.750599 | H162: 104.61664 | I162: 150.14595 | J162: Measure 3 | K162: Country
... A175: UNITED STATES | B175: 2404 | C175: 6.4883952 | D175: 38.265856 | E175: 241.40681 | F175: 35.152491 | G175: 18.823197 | H175: 25.286569 | I175: 42.458241 | J175: Measure 3 | K175: Country
A176: Grand Total | B176: 3082 | C176: 0.79162705 | D176: 43.267772 | E176: 451.00995 | F176: 43.611559 | G176: #NUM! | H176: #NUM! | I176: #NUM! | J176: #NUM! | K176: Country
A301: ALBERTA CANADA | B301: 8 | C301: 30.969402 | D301: 55.277661 | E301: 94.740997 | F301: 21.314668 | G301: 40.735664 | H301: 47.015396 | I301: 73.153612 | J301: Measure 3 | K301: Region
A302: MONTREAL MSA | B302: 8 | C302: 1.0704931 | D302: 7.2011683 | E302: 17.328014 | F302: 5.6710084 | G302: 3.1311655 | H302: 5.5850432 | I302: 12.395072 | J302: Measure 3 | K302: Region
A303: YUCATAN PENINSULA MEXICO | B303: 8 | C303: 35.410332 | D303: 57.920461 | E303: 140.98001 | F303: 36.113912 | G303: 36.962901 | H303: 43.246998 | I303: 69.845156 | J303: Measure 3 | K303: Region
A304: JAVA ISLAND INDONESIA | B304: 9 | C304: 75.472031 | D304: 153.45258 | E304: 451.00995 | F304: 116.51485 | G304: 93.975594 | H304: 106.03356 | I304: 163.20823 | J304: Measure 3 | K304: Region
A305: GUANGDONG CHINA | B305: 10 | C305: 14.957218 | D305: 97.381743 | E305: 142.07732 | F305: 40.15635 | G305: 64.430501 | H305: 116.19427 | I305: 125.34504 | J305: Measure 3 | K305: Region
A306: MAHARASHTRA INDIA | B306: 10 | C306: 58.57412 | D306: 109.60085 | E306: 180.42628 | F306: 45.073662 | G306: 77.497332 | H306: 94.563541 | I306: 166.89037 | J306: Measure 3 | K306: Region
A307: BANGKOK 200KM | B307: 11 | C307: 28.366102 | D307: 72.54412 | E307: 174.27077 | F307: 42.304657 | G307: 42.489937 | H307: 65.362228 | I307: 102.00991 | J307: Measure 3 | K307: Region
A308: BAJIO-CENTRAL MEXICO | B308: 11 | C308: 17.47257 | D308: 46.855003 | E308: 101.21519 | F308: 27.626132 | G308: 18.455164 | H308: 46.480499 | I308: 73.844017 | J308: Measure 3 | K308: Region
A309: NORTHERN MEXICO | B309: 12 | C309: 24.060072 | D309: 65.045446 | E309: 117.21274 | F309: 27.8765 | G309: 41.703519 | H309: 61.518368 | I309: 85.734835 | J309: Measure 3 | K309: Region
A310: SOUTHERN GERMANY | B310: 17 | C310: 14.766147 | D310: 29.920324 | E310: 95.261505 | F310: 22.090343 | G310: 16.464494 | H310: 22.095289 | I310: 33.014689 | J310: Measure 3 | K310: Region
A311: NORTHERN GERMANY | B311: 19 | C311: 8.835659 | D311: 28.475312 | E311: 66.401451 | F311: 14.125395 | G311: 16.183271 | H311: 27.88209 | I311: 38.573833 | J311: Measure 3 | K311: Region
...

Sheet ImpM4
A1: Row Labels | B1: Count | C1: Min | D1: Mean | E1: Max | F1: SD | G1: 25th | H1: Median | I1: 75th | J1: Measure | K1: Geography
A2: Knoxville, TN | B2: 8 | C2: 83.660316 | D2: 131.7961 | E2: 220.61139 | F2: 44.040403 | G2: 97.720434 | H2: 123.8014 | I2: 154.79447 | J2: Measure 4 | K2: MSA
A3: Montgomery, AL | B3: 8 | C3: 67.861847 | D3: 130.40143 | E3: 227.33363 | F3: 60.960586 | G3: 91.128939 | H3: 110.794 | I3: 197.5652 | J3: Measure 4 | K3: MSA
A4: Dayton, OH | B4: 8 | C4: 109.72863 | D4: 152.44771 | E4: 237.64542 | F4: 40.93689 | G4: 123.28163 | H4: 139.77714 | I4: 172.79325 | J4: Measure 4 | K4: MSA
A5: Greensboro-High Point, NC | B5: 8 | C5: 46.87038 | D5: 125.06198 | E5: 356.27365 | F5: 100.3148 | G5: 58.330717 | H5: 92.429745 | I5: 143.43888 | J5: Measure 4 | K5: MSA
A6: Albany-Schenectady-Troy, NY | B6: 8 | C6: 45.176414 | D6: 63.571647 | E6: 97.162003 | F6: 19.085894 | G6: 48.89928 | H6: 54.670202 | I6: 80.24329 | J6: Measure 4 | K6: MSA
A7: BANGKOK | B7: 8 | C7: 101.13319 | D7: 153.71217 | E7: 248.52565 | F7: 50.286423 | G7: 112.3767 | H7: 138.97126 | I7: 193.8103 | J7: Measure 4 | K7: MSA
A8: MONTREAL | B8: 8 | C8: 4.2192593 | D8: 39.021499 | E8: 88.560234 | F8: 30.141525 | G8: 17.009631 | H8: 27.151309 | I8: 70.311811 | J8: Measure 4 | K8: MSA
A9: BIRMINGHAM | B9: 8 | C9: 60.236031 | D9: 152.02078 | E9: 461.64948 | F9: 128.58344 | G9: 87.473368 | H9: 116.64573 | I9: 141.57534 | J9: Measure 4 | K9: MSA
A10: SAO PAULO | B10: 8 | C10: 23.914127 | D10: 65.740609 | E10: 240.16194 | F10: 71.467298 | G10: 32.324599 | H10: 42.669847 | I10: 56.711342 | J10: Measure 4 | K10: MSA
A11: DOHA | B11: 8 | C11: 46.036983 | D11: 155.46621 | E11: 346.22995 | F11: 100.23676 | G11: 67.195355 | H11: 147.97783 | I11: 217.59278 | J11: Measure 4 | K11: MSA
A12: Albuquerque, NM | B12: 9 | C12: 65.399239 | D12: 105.32415 | E12: 160.08473 | F12: 36.821119 | G12: 70.200256 | H12: 90.873497 | I12: 139.77264 | J12: Measure 4 | K12: MSA
A13: Raleigh, NC | B13: 9 | C13: 64.034477 | D13: 90.017563 | E13: 111.36009 | F13: 13.806126 | G13: 81.900589 | H13: 92.484703 | I13: 99.741051 | J13: Measure 4 | K13: MSA
... A76: Washington-Arlington-Alexandria, DC-VA-MD-WV | B76: 103 | C76: 58.252228 | D76: 114.33707 | E76: 308.6199 | F76: 37.994749 | G76: 91.53421 | H76: 106.53425 | I76: 132.96442 | J76: Measure 4 | K76: MSA
A77: Grand Total | B77: 1849 | C77: 4.2192593 | D77: 121.29727 | E77: 685.81555 | F77: 60.648556 | G77: #NUM! | H77: #NUM! | I77: #NUM! | J77: #NUM! | K77: MSA
A151: EGYPT | B151: 8 | C151: 116.14302 | D151: 177.44272 | E151: 301.85715 | F151: 68.955305 | G151: 123.05092 | H151: 150.07078 | I151: 242.07383 | J151: Measure 4 | K151: Country
A152: SPAIN | B152: 8 | C152: 30.851505 | D152: 119.36566 | E152: 308.26239 | F152: 80.733075 | G152: 92.592703 | H152: 102.44713 | I152: 115.05559 | J152: Measure 4 | K152: Country
A153: QATAR | B153: 9 | C153: 46.036983 | D153: 152.79083 | E153: 346.22995 | F153: 94.105793 | G153: 72.11907 | H153: 131.38783 | I153: 205.63446 | J153: Measure 4 | K153: Country
A154: TURKEY | B154: 9 | C154: 46.585678 | D154: 146.14856 | E154: 296.4902 | F154: 86.09018 | G154: 86.046867 | H154: 117.89312 | I154: 227.8298 | J154: Measure 4 | K154: Country
A155: MALAYSIA | B155: 10 | C155: 142.748 | D155: 268.59578 | E155: 725.79858 | F155: 172.63136 | G155: 161.28451 | H155: 222.09435 | I155: 317.89815 | J155: Measure 4 | K155: Country
A156: KOREA | B156: 10 | C156: 82.171173 | D156: 185.93215 | E156: 347.14038 | F156: 78.268224 | G156: 129.66962 | H156: 184.04959 | I156: 228.37009 | J156: Measure 4 | K156: Country
A157: BRAZIL | B157: 10 | C157: 23.914127 | D157: 59.54723 | E157: 240.16194 | F157: 64.425595 | G157: 31.450837 | H157: 38.33284 | I157: 55.089516 | J157: Measure 4 | K157: Country
A158: COSTA RICA | B158: 10 | C158: 18.756018 | D158: 44.199429 | E158: 86.012306 | F158: 24.012537 | G158: 25.36086 | H158: 40.743244 | I158: 60.749031 | J158: Measure 4 | K158: Country
A159: SWITZERLAND | B159: 10 | C159: 3.1199071 | D159: 35.843866 | E159: 92.755196 | F159: 34.259651 | G159: 11.885284 | H159: 19.381652 | I159: 74.458687 | J159: Measure 4 | K159: Country
A160: AUSTRIA | B160: 11 | C160: 18.303869 | D160: 65.822435 | E160: 118.96146 | F160: 27.892001 | G160: 47.478226 | H160: 63.836319 | I160: 89.200577 | J160: Measure 4 | K160: Country
A161: AUSTRALIA | B161: 12 | C161: 105.23118 | D161: 194.48745 | E161: 310.24631 | F161: 64.05599 | G161: 155.18393 | H161: 165.98635 | I161: 265.31185 | J161: Measure 4 | K161: Country
A162: INDONESIA | B162: 13 | C162: 192.80312 | D162: 252.9059 | E162: 358.75482 | F162: 55.806544 | G162: 217.31053 | H162: 228.34821 | I162: 290.87761 | J162: Measure 4 | K162: Country
... A176: UNITED STATES | B176: 2309 | C176: 25.328175 | D176: 118.62597 | E176: 546.92566 | F176: 55.199482 | G176: 82.192669 | H176: 109.60432 | I176: 141.44128 | J176: Measure 4 | K176: Country
A177: Grand Total | B177: 3011 | C177: 3.1199071 | D177: 125.82714 | E177: 867.99554 | F177: 69.838443 | G177: #NUM! | H177: #NUM! | I177: #NUM! | J177: #NUM! | K177: Country
A301: ALBERTA CANADA | B301: 8 | C301: 68.974045 | D301: 160.04304 | E301: 216.48567 | F301: 45.420504 | G301: 136.11372 | H301: 171.67789 | I301: 189.93564 | J301: Measure 4 | K301: Region
A302: JAVA ISLAND INDONESIA | B302: 9 | C302: 192.80312 | D302: 252.37783 | E302: 358.75482 | F302: 62.488357 | G302: 211.58827 | H302: 228.34821 | I302: 306.21317 | J302: Measure 4 | K302: Region
A303: MONTREAL MSA | B303: 9 | C303: 4.2192593 | D303: 36.959874 | E303: 88.560234 | F303: 28.865209 | G303: 17.62069 | H303: 24.144812 | I303: 63.300182 | J303: Measure 4 | K303: Region
A304: BANGKOK 200KM | B304: 10 | C304: 101.13319 | D304: 151.20892 | E304: 248.52565 | F304: 45.368859 | G304: 120.29857 | H304: 138.97126 | I304: 175.57468 | J304: Measure 4 | K304: Region
A305: BAJIO-CENTRAL MEXICO | B305: 10 | C305: 40.475494 | D305: 124.69645 | E305: 210.95746 | F305: 59.299053 | G305: 68.084053 | H305: 121.57507 | I305: 185.05006 | J305: Measure 4 | K305: Region
A306: MAHARASHTRA INDIA | B306: 10 | C306: 136.65884 | D306: 219.01459 | E306: 350.36493 | F306: 63.994649 | G306: 171.08038 | H306: 218.78403 | I306: 259.15387 | J306: Measure 4 | K306: Region
A307: GUANGDONG CHINA | B307: 11 | C307: 88.372925 | D307: 163.68946 | E307: 269.14832 | F307: 54.921278 | G307: 113.3908 | H307: 150.821 | I307: 207.53575 | J307: Measure 4 | K307: Region
A308: NORTHERN MEXICO | B308: 11 | C308: 64.356049 | D308: 155.04171 | E308: 303.4407 | F308: 75.995814 | G308: 84.401123 | H308: 145.81064 | I308: 202.82997 | J308: Measure 4 | K308: Region
A309: SOUTHERN GERMANY | B309: 17 | C309: 78.641533 | D309: 120.79589 | E309: 175.40753 | F309: 28.565448 | G309: 94.609417 | H309: 115.86284 | I309: 141.00003 | J309: Measure 4 | K309: Region
A310: NORTHERN GERMANY | B310: 19 | C310: 55.768959 | D310: 106.97032 | E310: 182.13664 | F310: 34.414904 | G310: 83.446297 | H310: 101.17374 | I310: 125.76774 | J310: Measure 4 | K310: Region
A311: Toronto 200KM | B311: 22 | C311: 25.796165 | D311: 69.908676 | E311: 230.77469 | F311: 51.013749 | G311: 41.600201 | H311: 54.70578 | I311: 72.375416 | J311: Measure 4 | K311: Region
...

Sheet ImpM5
A1: Row Labels | B1: Count | C1: Min | D1: Mean | E1: Max | F1: SD | G1: 25th | H1: Median | I1: 75th | J1: Measure | K1: Geography
A2: Albany-Schenectady-Troy, NY | B2: 8 | C2: 43.807991 | D2: 162.67096 | E2: 770.86664 | F2: 246.74747 | G2: 58.761433 | H2: 77.677361 | I2: 106.51088 | J2: Measure 5 | K2: MSA
A3: BANGKOK | B3: 8 | C3: 57.352352 | D3: 160.57394 | E3: 410.83289 | F3: 114.71442 | G3: 78.968281 | H3: 131.20547 | I3: 208.18081 | J3: Measure 5 | K3: MSA
A4: Las Vegas-Henderson-Paradise, NV | B4: 8 | C4: 47.000053 | D4: 141.90221 | E4: 459.79401 | F4: 162.24847 | G4: 54.116976 | H4: 59.117723 | I4: 269.74807 | J4: Measure 5 | K4: MSA
A5: BIRMINGHAM | B5: 8 | C5: 27.959156 | D5: 75.818221 | E5: 152.58652 | F5: 35.591712 | G5: 57.652668 | H5: 71.019173 | I5: 83.055206 | J5: Measure 5 | K5: MSA
A6: Wichita, KS | B6: 8 | C6: 53.142056 | D6: 171.466 | E6: 412.87985 | F6: 142.85742 | G6: 56.902199 | H6: 108.89899 | I6: 322.20566 | J6: Measure 5 | K6: MSA
A7: ISTANBUL | B7: 8 | C7: 52.619923 | D7: 184.69493 | E7: 379.17682 | F7: 126.52533 | G7: 73.093914 | H7: 157.69879 | I7: 322.67056 | J7: Measure 5 | K7: MSA
A8: Raleigh, NC | B8: 9 | C8: 36.332882 | D8: 57.591107 | E8: 86.469467 | F8: 20.559474 | G8: 39.995476 | H8: 48.385254 | I8: 82.163971 | J8: Measure 5 | K8: MSA
A9: JAVA ISLAND INDONESIA | B9: 9 | C9: 120.63063 | D9: 246.07398 | E9: 686.54883 | F9: 173.72752 | G9: 147.87103 | H9: 197.34045 | I9: 264.70991 | J9: Measure 5 | K9: MSA
A10: Durham-Chapel Hill, NC | B10: 9 | C10: 38.949749 | D10: 63.053329 | E10: 102.8977 | F10: 26.926 | G10: 41.477018 | H10: 46.454063 | I10: 94.85918 | J10: Measure 5 | K10: MSA
A11: Oklahoma City, OK | B11: 9 | C11: 40.821472 | D11: 96.333534 | E11: 333.82141 | F11: 94.324623 | G11: 45.490036 | H11: 60.30088 | I11: 113.50559 | J11: Measure 5 | K11: MSA
A12: Lexington-Fayette, KY | B12: 9 | C12: 36.950565 | D12: 69.203249 | E12: 138.97127 | F12: 34.13815 | G12: 47.122751 | H12: 61.08762 | I12: 89.618996 | J12: Measure 5 | K12: MSA
A13: Providence-Warwick, RI-MA | B13: 10 | C13: 44.839428 | D13: 79.792063 | E13: 150.26129 | F13: 32.818538 | G13: 56.370193 | H13: 67.78981 | I13: 98.623291 | J13: Measure 5 | K13: MSA
... A72: Washington-Arlington-Alexandria, DC-VA-MD-WV | B72: 111 | C72: 36.035511 | D72: 154.35458 | E72: 1120.6436 | F72: 224.54239 | G72: 56.689651 | H72: 76.958221 | I72: 135.96318 | J72: Measure 5 | K72: MSA
A73: Grand Total | B73: 1911 | C73: 25.05645 | D73: 130.14292 | E73: 1192.5508 | F73: 170.86401 | G73: #NUM! | H73: #NUM! | I73: #NUM! | J73: #NUM! | K73: MSA
A151: AUSTRIA | B151: 8 | C151: 31.450571 | D151: 84.904891 | E151: 194.55647 | F151: 51.614647 | G151: 51.236864 | H151: 68.2341 | I151: 109.29264 | J151: Measure 5 | K151: Country
A152: SPAIN | B152: 8 | C152: 41.348343 | D152: 175.82578 | E152: 447.37466 | F152: 122.58256 | G152: 89.204161 | H152: 162.95609 | I152: 197.98483 | J152: Measure 5 | K152: Country
A153: ITALY | B153: 8 | C153: 76.425797 | D153: 370.47687 | E153: 690.99408 | F153: 227.14623 | G153: 153.49919 | H153: 355.16 | I153: 594.90804 | J153: Measure 5 | K153: Country
A154: SWITZERLAND | B154: 8 | C154: 26.722221 | D154: 82.332911 | E154: 232.07478 | F154: 69.726219 | G154: 37.268791 | H154: 47.503901 | I154: 120.43006 | J154: Measure 5 | K154: Country
A155: JORDAN | B155: 9 | C155: 75.061691 | D155: 588.1156 | E155: 1064.6195 | F155: 421.32244 | G155: 173.13958 | H155: 720.57025 | I155: 1026.5199 | J155: Measure 5 | K155: Country
A156: BRAZIL | B156: 9 | C156: 28.654285 | D156: 152.14099 | E156: 600.01062 | F156: 172.60639 | G156: 72.939209 | H156: 97.738823 | I156: 153.10143 | J156: Measure 5 | K156: Country
A157: KOREA | B157: 10 | C157: 81.787842 | D157: 199.12522 | E157: 276.01559 | F157: 70.680944 | G157: 147.68471 | H157: 209.6943 | I157: 257.67686 | J157: Measure 5 | K157: Country
A158: COSTA RICA | B158: 10 | C158: 34.312645 | D158: 96.573441 | E158: 203.44859 | F158: 49.195788 | G158: 61.394569 | H158: 88.736797 | I158: 123.5864 | J158: Measure 5 | K158: Country
A159: TURKEY | B159: 10 | C159: 52.619923 | D159: 247.60224 | E159: 630.74933 | F159: 184.07356 | G159: 105.41643 | H159: 180.6937 | I159: 371.8545 | J159: Measure 5 | K159: Country
A160: AUSTRALIA | B160: 12 | C160: 29.147009 | D160: 93.954354 | E160: 182.79471 | F160: 51.62764 | G160: 48.712523 | H160: 85.023773 | I160: 133.8496 | J160: Measure 5 | K160: Country
A161: HONG KONG | B161: 14 | C161: 47.401649 | D161: 142.21522 | E161: 342.03497 | F161: 88.723605 | G161: 72.87635 | H161: 113.37967 | I161: 201.28979 | J161: Measure 5 | K161: Country
A162: INDONESIA | B162: 14 | C162: 82.524574 | D162: 239.42107 | E162: 686.54883 | F162: 175.25575 | G162: 132.97788 | H162: 181.03995 | I162: 251.16037 | J162: Measure 5 | K162: Country
... A175: UNITED STATES | B175: 2404 | C175: 25.435644 | D175: 126.524 | E175: 1221.502 | F175: 176.49401 | G175: 48.470979 | H175: 63.26265 | I175: 107.33214 | J175: Measure 5 | K175: Country
A176: Grand Total | B176: 3082 | C176: 25.025223 | D176: 134.65898 | E176: 1221.502 | F176: 173.91645 | G176: #NUM! | H176: #NUM! | I176: #NUM! | J176: #NUM! | K176: Country
A301: ALBERTA CANADA | B301: 8 | C301: 36.102905 | D301: 135.29742 | E301: 283.00378 | F301: 73.798744 | G301: 98.876398 | H301: 112.65759 | I301: 172.52954 | J301: Measure 5 | K301: Region
A302: MONTREAL MSA | B302: 8 | C302: 51.692516 | D302: 91.734217 | E302: 152.73357 | F302: 33.952333 | G302: 63.76494 | H302: 84.520035 | I302: 119.23685 | J302: Measure 5 | K302: Region
A303: YUCATAN PENINSULA MEXICO | B303: 8 | C303: 93.149582 | D303: 188.22603 | E303: 496.43088 | F303: 137.9265 | G303: 115.71393 | H303: 127.04745 | I303: 249.57948 | J303: Measure 5 | K303: Region
A304: JAVA ISLAND INDONESIA | B304: 9 | C304: 120.63063 | D304: 246.07398 | E304: 686.54883 | F304: 173.72752 | G304: 147.87103 | H304: 197.34045 | I304: 264.70991 | J304: Measure 5 | K304: Region
A305: GUANGDONG CHINA | B305: 10 | C305: 35.964863 | D305: 197.88607 | E305: 278.2157 | F305: 73.724919 | G305: 143.59477 | H305: 228.33443 | I305: 245.00685 | J305: Measure 5 | K305: Region
A306: MAHARASHTRA INDIA | B306: 10 | C306: 78.497757 | D306: 173.7161 | E306: 295.78088 | F306: 79.393112 | G306: 113.73803 | H306: 143.22399 | I306: 257.03503 | J306: Measure 5 | K306: Region
A307: BANGKOK 200KM | B307: 11 | C307: 57.352352 | D307: 162.63523 | E307: 410.83289 | F307: 98.673438 | G307: 98.56321 | H307: 156.99529 | I307: 223.38951 | J307: Measure 5 | K307: Region
A308: BAJIO-CENTRAL MEXICO | B308: 11 | C308: 49.912437 | D308: 212.25432 | E308: 764.3667 | F308: 218.01228 | G308: 57.167648 | H308: 162.31769 | I308: 233.3009 | J308: Measure 5 | K308: Region
A309: NORTHERN MEXICO | B309: 12 | C309: 88.496918 | D309: 258.8592 | E309: 489.82343 | F309: 121.73049 | G309: 171.67811 | H309: 236.12959 | I309: 353.92413 | J309: Measure 5 | K309: Region
A310: SOUTHERN GERMANY | B310: 17 | C310: 41.290855 | D310: 91.359527 | E310: 299.97653 | F310: 70.344398 | G310: 48.307985 | H310: 65.502274 | I310: 105.32798 | J310: Measure 5 | K310: Region
A311: NORTHERN GERMANY | B311: 19 | C311: 29.822695 | D311: 81.410629 | E311: 168.89986 | F311: 35.246919 | G311: 52.782303 | H311: 79.904831 | I311: 108.0275 | J311: Measure 5 | K311: Region
...

Sheet ImpM6
A1: Row Labels | B1: Count | C1: Min | D1: Mean | E1: Max | F1: SD | G1: 25th | H1: Median | I1: 75th | J1: Measure | K1: Geography
A2: Knoxville, TN | B2: 8 | C2: 177.38025 | D2: 446.50014 | E2: 1217.0597 | F2: 381.42235 | G2: 218.67192 | H2: 267.56749 | I2: 729.47654 | J2: Measure 6 | K2: MSA
A3: Montgomery, AL | B3: 8 | C3: 109.93546 | D3: 270.4896 | E3: 557.33679 | F3: 149.30052 | G3: 184.80232 | H3: 217.14272 | I3: 389.58522 | J3: Measure 6 | K3: MSA
A4: Dayton, OH | B4: 8 | C4: 213.29135 | D4: 334.56869 | E4: 668.28485 | F4: 147.03584 | G4: 237.40207 | H4: 298.99248 | I4: 380.08146 | J4: Measure 6 | K4: MSA
A5: Greensboro-High Point, NC | B5: 8 | C5: 96.06601 | D5: 306.1984 | E5: 685.84241 | F5: 187.9872 | G5: 159.45303 | H5: 268.47189 | I5: 397.71194 | J5: Measure 6 | K5: MSA
A6: Albany-Schenectady-Troy, NY | B6: 8 | C6: 195.13519 | D6: 290.77392 | E6: 451.88611 | F6: 91.882133 | G6: 221.66654 | H6: 250.25784 | I6: 370.76911 | J6: Measure 6 | K6: MSA
A7: BANGKOK | B7: 8 | C7: 204.47739 | D7: 342.55923 | E7: 585.88434 | F7: 135.48452 | G7: 226.21286 | H7: 299.8194 | I7: 463.60331 | J7: Measure 6 | K7: MSA
A8: MONTREAL | B8: 8 | C8: 297.56339 | D8: 498.60466 | E8: 996.66675 | F8: 229.86398 | G8: 350.58418 | H8: 423.21744 | I8: 616.97082 | J8: Measure 6 | K8: MSA
A9: BIRMINGHAM | B9: 8 | C9: 153.48843 | D9: 504.34178 | E9: 1465.7301 | F9: 418.20593 | G9: 257.74483 | H9: 369.42117 | I9: 582.54344 | J9: Measure 6 | K9: MSA
A10: SAO PAULO | B10: 8 | C10: 236.4547 | D10: 487.98462 | E10: 1295.2732 | F10: 340.26043 | G10: 295.51657 | H10: 396.73073 | I10: 508.23956 | J10: Measure 6 | K10: MSA
A11: DOHA | B11: 8 | C11: 104.75034 | D11: 407.87985 | E11: 1124.6052 | F11: 337.77881 | G11: 154.75112 | H11: 325.53795 | I11: 585.37741 | J11: Measure 6 | K11: MSA
A12: Albuquerque, NM | B12: 9 | C12: 173.88251 | D12: 289.35709 | E12: 522.55316 | F12: 128.39881 | G12: 184.21684 | H12: 216.80118 | I12: 402.14561 | J12: Measure 6 | K12: MSA
A13: Raleigh, NC | B13: 9 | C13: 174.03853 | D13: 240.10042 | E13: 289.09763 | F13: 36.463449 | G13: 217.75058 | H13: 238.18774 | I13: 274.09212 | J13: Measure 6 | K13: MSA
... A76: Washington-Arlington-Alexandria, DC-VA-MD-WV | B76: 103 | C76: 118.97184 | D76: 317.46773 | E76: 930.07489 | F76: 121.62703 | G76: 232.94513 | H76: 286.37936 | I76: 369.92993 | J76: Measure 6 | K76: MSA
A77: Grand Total | B77: 1849 | C77: 94.783234 | D77: 323.23886 | E77: 1487.6547 | F77: 160.25611 | G77: #NUM! | H77: #NUM! | I77: #NUM! | J77: #NUM! | K77: MSA
A151: EGYPT | B151: 8 | C151: 326.31525 | D151: 584.86275 | E151: 1309.126 | F151: 335.39164 | G151: 344.57376 | H151: 444.91087 | I151: 764.21782 | J151: Measure 6 | K151: Country
A152: SPAIN | B152: 8 | C152: 129.27927 | D152: 484.53145 | E152: 1437.8835 | F152: 396.59677 | G152: 342.33752 | H152: 390.31122 | I152: 420.87041 | J152: Measure 6 | K152: Country
A153: QATAR | B153: 9 | C153: 104.75034 | D153: 394.96153 | E153: 1124.6052 | F153: 318.33105 | G153: 168.25039 | H153: 291.61496 | I153: 523.05328 | J153: Measure 6 | K153: Country
A154: TURKEY | B154: 9 | C154: 206.57004 | D154: 495.96012 | E154: 1313.906 | F154: 389.46426 | G154: 238.11406 | H154: 306.35934 | I154: 772.05325 | J154: Measure 6 | K154: Country
A155: MALAYSIA | B155: 10 | C155: 241.78802 | D155: 473.69212 | E155: 1318.6499 | F155: 318.37136 | G155: 270.18158 | H155: 378.82343 | I155: 552.47281 | J155: Measure 6 | K155: Country
A156: KOREA | B156: 10 | C156: 201.51443 | D156: 511.02563 | E156: 946.1756 | F156: 216.60635 | G156: 358.73242 | H156: 497.563 | I156: 628.29179 | J156: Measure 6 | K156: Country
A157: BRAZIL | B157: 10 | C157: 236.4547 | D157: 450.18479 | E157: 1295.2732 | F157: 310.49775 | G157: 292.05614 | H157: 327.60532 | I157: 470.37457 | J157: Measure 6 | K157: Country
A158: COSTA RICA | B158: 10 | C158: 163.38683 | D158: 342.02927 | E158: 636.59747 | F158: 145.50335 | G158: 220.69955 | H158: 311.23361 | I158: 449.35358 | J158: Measure 6 | K158: Country
A159: SWITZERLAND | B159: 10 | C159: 105.31581 | D159: 309.40271 | E159: 741.73895 | F159: 234.86509 | G159: 164.51322 | H159: 195.76276 | I159: 506.69537 | J159: Measure 6 | K159: Country
A160: AUSTRIA | B160: 11 | C160: 84.952332 | D160: 308.413 | E160: 553.68146 | F160: 131.82441 | G160: 220.97757 | H160: 299.69409 | I160: 421.60638 | J160: Measure 6 | K160: Country
A161: AUSTRALIA | B161: 12 | C161: 189.9034 | D161: 305.34869 | E161: 468.63727 | F161: 102.95504 | G161: 209.46561 | H161: 266.29185 | I161: 406.17844 | J161: Measure 6 | K161: Country
A162: INDONESIA | B162: 13 | C162: 302.48212 | D162: 407.11675 | E162: 558.67963 | F162: 84.371256 | G162: 332.52414 | H162: 394.37415 | I162: 462.57129 | J162: Measure 6 | K162: Country
... A176: UNITED STATES | B176: 2309 | C176: 85.601479 | D176: 309.35714 | E176: 1493.6742 | F176: 152.4563 | G176: 224.16158 | H176: 268.49527 | I176: 348.592 | J176: Measure 6 | K176: Country
A177: Grand Total | B177: 3011 | C177: 84.324242 | D177: 333.34214 | E177: 1493.6742 | F177: 180.05957 | G177: #NUM! | H177: #NUM! | I177: #NUM! | J177: #NUM! | K177: Country
A301: ALBERTA CANADA | B301: 8 | C301: 156.34502 | D301: 370.93073 | E301: 538.42657 | F301: 135.0389 | G301: 235.19762 | H301: 398.85611 | I301: 478.74261 | J301: Measure 6 | K301: Region
A302: JAVA ISLAND INDONESIA | B302: 9 | C302: 309.3269 | D302: 409.07345 | E302: 558.67963 | F302: 90.434458 | G302: 332.52414 | H302: 394.37415 | I302: 485.54776 | J302: Measure 6 | K302: Region
A303: MONTREAL MSA | B303: 9 | C303: 192.85547 | D303: 464.63252 | E303: 996.66675 | F303: 237.94899 | G303: 320.55977 | H303: 412.09543 | I303: 566.47392 | J303: Measure 6 | K303: Region
A304: BANGKOK 200KM | B304: 10 | C304: 204.47739 | D304: 334.27173 | E304: 585.88434 | F304: 121.07064 | G304: 251.73967 | H304: 299.8194 | I304: 408.91747 | J304: Measure 6 | K304: Region
A305: BAJIO-CENTRAL MEXICO | B305: 10 | C305: 114.99345 | D305: 432.31909 | E305: 963.84985 | F305: 250.8116 | G305: 195.85865 | H305: 455.25621 | I305: 568.43564 | J305: Measure 6 | K305: Region
A306: MAHARASHTRA INDIA | B306: 10 | C306: 198.68054 | D306: 341.81752 | E306: 574.3689 | F306: 109.30902 | G306: 257.40424 | H306: 331.08539 | I306: 401.5186 | J306: Measure 6 | K306: Region
A307: GUANGDONG CHINA | B307: 11 | C307: 212.49408 | D307: 344.65859 | E307: 620.42639 | F307: 122.24962 | G307: 250.7543 | H307: 302.91125 | I307: 414.12448 | J307: Measure 6 | K307: Region
A308: NORTHERN MEXICO | B308: 11 | C308: 271.58276 | D308: 598.13909 | E308: 1066.3563 | F308: 283.41622 | G308: 302.41318 | H308: 552.177 | I308: 845.28845 | J308: Measure 6 | K308: Region
A309: SOUTHERN GERMANY | B309: 17 | C309: 214.46342 | D309: 360.85546 | E309: 555.47919 | F309: 90.814297 | G309: 289.19926 | H309: 350.47623 | I309: 406.61203 | J309: Measure 6 | K309: Region
A310: NORTHERN GERMANY | B310: 19 | C310: 165.3913 | D310: 315.27182 | E310: 604.23572 | F310: 109.19561 | G310: 231.50606 | H310: 301.49591 | I310: 367.1684 | J310: Measure 6 | K310: Region
A311: Toronto 200KM | B311: 22 | C311: 171.91812 | D311: 429.65916 | E311: 1298.536 | F311: 281.4473 | G311: 264.40724 | H311: 350.62271 | I311: 449.55668 | J311: Measure 6 | K311: Region
...

Sheet ImpM7
A1: Row Labels | B1: Count | C1: Min | D1: Mean | E1: Max | F1: SD | G1: 25th | H1: Median | I1: 75th | J1: Measure | K1: Geography
A2: TORONTO | B2: 8 | C2: 0.0099177282 | D2: 0.015618795 | E2: 0.025611802 | F2: 0.0050025532 | G2: 0.011167568 | H2: 0.014994088 | I2: 0.018156737 | J2: Measure 7 | K2: MSA
A3: Tucson, AZ | B3: 8 | C3: 0.018302319 | D3: 0.03236957 | E3: 0.047689549 | F3: 0.010674983 | G3: 0.025722007 | H3: 0.0277697 | I3: 0.044632557 | J3: Measure 7 | K3: MSA
A4: Las Vegas-Henderson-Paradise, NV | B4: 8 | C4: 0.019745356 | D4: 0.026809409 | E4: 0.044327709 | F4: 0.0077404166 | G4: 0.021608809 | H4: 0.024281335 | I4: 0.028706802 | J4: Measure 7 | K4: MSA
A5: Albuquerque, NM | B5: 8 | C5: 0.017917601 | D5: 0.030717007 | E5: 0.048244713 | F5: 0.010869093 | G5: 0.02083364 | H5: 0.029938402 | I5: 0.039751286 | J5: Measure 7 | K5: MSA
A6: Oklahoma City, OK | B6: 8 | C6: 0.03172777 | D6: 0.043788652 | E6: 0.074930084 | F6: 0.014113563 | G6: 0.034200952 | H6: 0.039854522 | I6: 0.049805568 | J6: Measure 7 | K6: MSA
A7: JAVA ISLAND INDONESIA | B7: 8 | C7: 0.052822754 | D7: 0.072731013 | E7: 0.10745244 | F7: 0.019516023 | G7: 0.060152715 | H7: 0.06573682 | I7: 0.091242723 | J7: Measure 7 | K7: MSA
A8: Durham-Chapel Hill, NC | B8: 8 | C8: 0.017159622 | D8: 0.029543017 | E8: 0.050204398 | F8: 0.011034313 | G8: 0.020690265 | H8: 0.027791286 | I8: 0.037808452 | J8: Measure 7 | K8: MSA
A9: BANGKOK | B9: 8 | C9: 0.030478497 | D9: 0.043298763 | E9: 0.06808924 | F9: 0.012870361 | G9: 0.033015494 | H9: 0.039947374 | I9: 0.053098711 | J9: Measure 7 | K9: MSA
A10: St. Louis, MO-IL | B10: 9 | C10: 0.033698055 | D10: 0.04755306 | E10: 0.067232566 | F10: 0.012936994 | G10: 0.034978628 | H10: 0.042985796 | I10: 0.05938856 | J10: Measure 7 | K10: MSA
A11: San Jose-Sunnyvale-Santa Clara, CA | B11: 9 | C11: 0.01118436 | D11: 0.018524288 | E11: 0.030749544 | F11: 0.0060247618 | G11: 0.013838388 | H11: 0.017580081 | I11: 0.022395047 | J11: Measure 7 | K11: MSA
A12: Salt Lake City, UT | B12: 9 | C12: 0.018802588 | D12: 0.024483819 | E12: 0.036791898 | F12: 0.0061294734 | G12: 0.019314757 | H12: 0.023180376 | I12: 0.029268735 | J12: Measure 7 | K12: MSA
A13: Rochester, NY | B13: 9 | C13: 0.01843674 | D13: 0.027708006 | E13: 0.065409486 | F13: 0.014734396 | G13: 0.019442044 | H13: 0.023131432 | I13: 0.029405077 | J13: Measure 7 | K13: MSA
... A59: Washington-Arlington-Alexandria, DC-VA-MD-WV | B59: 74 | C59: 0.015959514 | D59: 0.033522247 | E59: 0.084553385 | F59: 0.011954939 | G59: 0.025730814 | H59: 0.029549676 | I59: 0.041449748 | J59: Measure 7 | K59: MSA
A60: Grand Total | B60: 1245 | C60: 0.0062608615 | D60: 0.035125022 | E60: 0.20668413 | F60: 0.017537444 | G60: #NUM! | H60: #NUM! | I60: #NUM! | J60: #NUM! | K60: MSA
A151: BRAZIL | B151: 8 | C151: 0.0087150487 | D151: 0.019634903 | E151: 0.072377567 | F151: 0.021503242 | G151: 0.0097416617 | H151: 0.012184019 | I151: 0.016208331 | J151: Measure 7 | K151: Country
A152: SWITZERLAND | B152: 8 | C152: 0.0031855071 | D152: 0.0096089407 | E152: 0.02541238 | F152: 0.0085269657 | G152: 0.004131518 | H152: 0.0056115394 | I152: 0.017425985 | J152: Measure 7 | K152: Country
A153: TURKEY | B153: 9 | C153: 0.0127632 | D153: 0.042197997 | E153: 0.081230195 | F153: 0.024355638 | G153: 0.02491914 | H153: 0.03552943 | I153: 0.066063008 | J153: Measure 7 | K153: Country
A154: MALAYSIA | B154: 10 | C154: 0.03910904 | D154: 0.074076236 | E154: 0.19884897 | F154: 0.047036787 | G154: 0.04418754 | H154: 0.06084778 | I154: 0.087095408 | J154: Measure 7 | K154: Country
A155: KOREA | B155: 10 | C155: 0.024763915 | D155: 0.054257255 | E155: 0.10461765 | F155: 0.022979581 | G155: 0.039078507 | H155: 0.05267965 | I155: 0.064179339 | J155: Measure 7 | K155: Country
A156: AUSTRALIA | B156: 11 | C156: 0.031713509 | D156: 0.056597294 | E156: 0.084998954 | F156: 0.017874548 | G156: 0.046124219 | H156: 0.048927013 | I156: 0.076238848 | J156: Measure 7 | K156: Country
A157: AUSTRIA | B157: 11 | C157: 0.0055162335 | D157: 0.019461384 | E157: 0.035851394 | F157: 0.0083019197 | G157: 0.014308505 | H157: 0.019238346 | I157: 0.02688237 | J157: Measure 7 | K157: Country
A158: INDONESIA | B158: 12 | C158: 0.052822754 | D158: 0.072173748 | E158: 0.10745244 | F158: 0.016573903 | G158: 0.061536863 | H158: 0.066233314 | I158: 0.082126086 | J158: Measure 7 | K158: Country
A159: HONG KONG | B159: 13 | C159: 0.038939941 | D159: 0.083527527 | E159: 0.16221106 | F159: 0.03254331 | G159: 0.061699014 | H159: 0.0766283 | I159: 0.10452805 | J159: Measure 7 | K159: Country
A160: THAILAND | B160: 14 | C160: 0.030478497 | D160: 0.0537495 | E160: 0.093921847 | F160: 0.022226061 | G160: 0.034055135 | H160: 0.044463451 | I160: 0.072210294 | J160: Measure 7 | K160: Country
A161: RUSSIAN FEDERATION | B161: 14 | C161: 0.026520629 | D161: 0.044476695 | E161: 0.07415852 | F161: 0.013814725 | G161: 0.033855426 | H161: 0.040210671 | I161: 0.055375589 | J161: Measure 7 | K161: Country
A162: SAUDI ARABIA | B162: 15 | C162: 0.069751821 | D162: 0.12463809 | E162: 0.237807 | F162: 0.044017283 | G162: 0.093356896 | H162: 0.12622965 | I162: 0.14635835 | J162: Measure 7 | K162: Country
... A172: UNITED STATES | B172: 1614 | C172: 0.0090872751 | D172: 0.033656191 | E172: 0.1495356 | F172: 0.015035189 | G172: 0.023342696 | H172: 0.031212459 | I172: 0.040264934 | J172: Measure 7 | K172: Country
A173: Grand Total | B173: 2199 | C173: 0.0010661577 | D173: 0.036665285 | E173: 0.237807 | F173: 0.020794012 | G173: #NUM! | H173: #NUM! | I173: #NUM! | J173: #NUM! | K173: Country
A301: JAVA ISLAND INDONESIA | B301: 8 | C301: 0.052822754 | D301: 0.072731013 | E301: 0.10745244 | F301: 0.019516023 | G301: 0.060152715 | H301: 0.06573682 | I301: 0.091242723 | J301: Measure 7 | K301: Region
A302: MONTREAL MSA | B302: 8 | C302: 0.0012715579 | D302: 0.010879884 | E302: 0.024263072 | F302: 0.008309001 | G302: 0.0047412843 | H302: 0.0077047002 | I302: 0.019601023 | J302: Measure 7 | K302: Region
A303: GUANGDONG CHINA | B303: 9 | C303: 0.03072265 | D303: 0.044552771 | E303: 0.061767498 | F303: 0.012048025 | G303: 0.034029134 | H303: 0.041320832 | I303: 0.058309832 | J303: Measure 7 | K303: Region
A304: BANGKOK 200KM | B304: 10 | C304: 0.030478497 | D304: 0.042375772 | E304: 0.06808924 | F304: 0.011721921 | G304: 0.033700962 | H304: 0.039947374 | I304: 0.048102651 | J304: Measure 7 | K304: Region
A305: MAHARASHTRA INDIA | B305: 10 | C305: 0.041184856 | D305: 0.062351689 | E305: 0.095990402 | F305: 0.015907682 | G305: 0.051558472 | H305: 0.06290311 | I305: 0.071001065 | J305: Measure 7 | K305: Region
A306: CARIBBEAN | B306: 14 | C306: 0.020894751 | D306: 0.057608857 | E306: 0.10866791 | F306: 0.027767116 | G306: 0.031930766 | H306: 0.05551704 | I306: 0.074547625 | J306: Measure 7 | K306: Region
A307: SOUTHERN GERMANY | B307: 17 | C307: 0.023700183 | D307: 0.036160678 | E307: 0.052862542 | F307: 0.0083897197 | G307: 0.028512434 | H307: 0.034917564 | I307: 0.040422846 | J307: Measure 7 | K307: Region
A308: Toronto 200KM | B308: 17 | C308: 0.0024582242 | D308: 0.020350352 | E308: 0.063225954 | F308: 0.015751823 | G308: 0.012101769 | H308: 0.015098678 | I308: 0.022144576 | J308: Measure 7 | K308: Region
A309: NORTHERN GERMANY | B309: 18 | C309: 0.016807086 | D309: 0.032444047 | E309: 0.049900454 | F309: 0.0097751004 | G309: 0.026081203 | H309: 0.032262596 | I309: 0.039378783 | J309: Measure 7 | K309: Region
A310: N/A | B310: 2205 | C310: 0.0002970679 | D310: 0.037427513 | E310: 0.237807 | F310: 0.022301064 | G310: 0.023601073 | H310: 0.032757828 | I310: 0.044571316 | J310: Measure 7 | K310: Region
A311: Grand Total | B311: 2316 | C311: 0.0002970679 | D311: 0.037563043 | E311: 0.237807 | F311: 0.02232989 | G311: #NUM! | H311: #NUM! | I311: #NUM! | J311: #NUM! | K311: Region
...

Sheet ImpM8
A1: Row Labels | B1: Count | C1: Min | D1: Mean | E1: Max | F1: SD | G1: 25th | H1: Median | I1: 75th | J1: Measure | K1: Geography
A2: JAVA ISLAND INDONESIA | B2: 8 | C2: 552.38113 | D2: 1888.2398 | E2: 3356.0358 | F2: 940.51433 | G2: 1125.4183 | H2: 1768.0829 | I2: 2781.0234 | J2: Measure 8 | K2: MSA
A3: Bridgeport-Stamford-Norwalk, CT | B3: 8 | C3: 78.923756 | D3: 397.65152 | E3: 585.16084 | F3: 165.30186 | G3: 323.45489 | H3: 387.38686 | I3: 561.45516 | J3: Measure 8 | K3: MSA
A4: Memphis, TN-MS-AR | B4: 8 | C4: 301.88629 | D4: 489.56118 | E4: 661.51562 | F4: 118.68047 | G4: 377.06005 | H4: 522.19106 | I4: 565.88139 | J4: Measure 8 | K4: MSA
A5: PARIS | B5: 8 | C5: 460.34228 | D5: 600.33553 | E5: 949.78716 | F5: 169.11809 | G5: 476.52565 | H5: 529.03782 | I5: 711.14985 | J5: Measure 8 | K5: MSA
A6: Savannah, GA | B6: 8 | C6: 264.31595 | D6: 502.90937 | E6: 701.00038 | F6: 182.26917 | G6: 321.25374 | H6: 486.70795 | I6: 694.75397 | J6: Measure 8 | K6: MSA
A7: Oklahoma City, OK | B7: 8 | C7: 476.72849 | D7: 634.00146 | E7: 1029.1395 | F7: 173.04434 | G7: 524.05968 | H7: 581.82997 | I7: 676.25676 | J7: Measure 8 | K7: MSA
A8: Sacramento--Roseville--Arden-Arcade, CA | B8: 9 | C8: 388.98397 | D8: 879.32524 | E8: 3102.3067 | F8: 849.2167 | G8: 516.52035 | H8: 587.79374 | I8: 804.5354 | J8: Measure 8 | K8: MSA
A9: Durham-Chapel Hill, NC | B9: 9 | C9: 336.66868 | D9: 420.2909 | E9: 586.65702 | F9: 75.717534 | G9: 369.73251 | H9: 392.28452 | I9: 463.15742 | J9: Measure 8 | K9: MSA
A10: Richmond, VA | B10: 9 | C10: 330.51449 | D10: 535.12833 | E10: 1025.2396 | F10: 199.20948 | G10: 415.611 | H10: 514.2787 | I10: 559.78666 | J10: Measure 8 | K10: MSA
A11: TORONTO | B11: 9 | C11: 504.95533 | D11: 734.85637 | E11: 1169.9997 | F11: 238.30796 | G11: 534.49061 | H11: 664.46226 | I11: 957.51721 | J11: Measure 8 | K11: MSA
A12: Raleigh, NC | B12: 9 | C12: 263.8415 | D12: 441.10537 | E12: 636.64988 | F12: 102.40459 | G12: 378.18093 | H12: 431.19158 | I12: 492.91208 | J12: Measure 8 | K12: MSA
A13: HONG KONG | B13: 9 | C13: 285.69405 | D13: 972.71614 | E13: 1765.6652 | F13: 520.2398 | G13: 503.56732 | H13: 903.05077 | I13: 1466.1756 | J13: Measure 8 | K13: MSA
... A65: Washington-Arlington-Alexandria, DC-VA-MD-WV | B65: 102 | C65: 50.084629 | D65: 555.81125 | E65: 2067.9319 | F65: 271.17433 | G65: 402.95894 | H65: 488.82694 | I65: 641.26158 | J65: Measure 8 | K65: MSA
A66: Grand Total | B66: 1610 | C66: 47.61991 | D66: 647.91702 | E66: 10833.188 | F66: 613.11422 | G66: #NUM! | H66: #NUM! | I66: #NUM! | J66: #NUM! | K66: MSA
A151: COSTA RICA | B151: 9 | C151: 459.96046 | D151: 1453.4614 | E151: 2775.6685 | F151: 900.69741 | G151: 567.11014 | H151: 1337.0688 | I151: 2337.2579 | J151: Measure 8 | K151: Country
A152: BRAZIL | B152: 9 | C152: 97.098956 | D152: 541.19149 | E152: 1167.1566 | F152: 320.75634 | G152: 287.34062 | H152: 499.98527 | I152: 758.17557 | J152: Measure 8 | K152: Country
A153: KOREA | B153: 9 | C153: 550.34964 | D153: 1661.6587 | E153: 2528.9587 | F153: 700.22747 | G153: 1078.9209 | H153: 1670.7281 | I153: 2342.3721 | J153: Measure 8 | K153: Country
A154: HONG KONG | B154: 10 | C154: 285.69405 | D154: 973.02971 | E154: 1765.6652 | F154: 490.48779 | G154: 509.27454 | H154: 939.4513 | I154: 1460.477 | J154: Measure 8 | K154: Country
A155: AUSTRALIA | B155: 11 | C155: 352.23747 | D155: 583.80482 | E155: 981.36667 | F155: 228.02004 | G155: 402.83263 | H155: 519.37632 | I155: 854.77583 | J155: Measure 8 | K155: Country
A156: THAILAND | B156: 13 | C156: 662.21712 | D156: 1525.1387 | E156: 2384.9265 | F156: 547.17971 | G156: 1076.8666 | H156: 1287.5672 | I156: 2050.2246 | J156: Measure 8 | K156: Country
A157: RUSSIAN FEDERATION | B157: 13 | C157: 297.74656 | D157: 806.767 | E157: 2280.4325 | F157: 581.95586 | G157: 366.94702 | H157: 584.76765 | I157: 1087.6955 | J157: Measure 8 | K157: Country
A158: INDONESIA | B158: 13 | C158: 552.38113 | D158: 2422.2637 | E158: 8971.1888 | F158: 2234.0147 | G158: 869.26212 | H158: 1810.9311 | I158: 3165.5707 | J158: Measure 8 | K158: Country
A159: JAPAN | B159: 14 | C159: 1000.9683 | D159: 2297.0265 | E159: 9521.648 | F159: 2126.6417 | G159: 1503.3787 | H159: 1740.6335 | I159: 2178.5622 | J159: Measure 8 | K159: Country
A160: MEXICO | B160: 16 | C160: 114.36908 | D160: 911.22026 | E160: 2117.0494 | F160: 565.53608 | G160: 381.57265 | H160: 844.0532 | I160: 1367.8545 | J160: Measure 8 | K160: Country
A161: FRANCE | B161: 18 | C161: 226.98494 | D161: 521.82402 | E161: 1415.8968 | F161: 295.14593 | G161: 282.63423 | H161: 481.27896 | I161: 636.97075 | J161: Measure 8 | K161: Country
A162: UNITED ARAB EMIRATES | B162: 21 | C162: 175.84056 | D162: 1117.5012 | E162: 5270.4646 | F162: 1326.9071 | G162: 350.40947 | H162: 761.64034 | I162: 1206.3095 | J162: Measure 8 | K162: Country
... A168: UNITED STATES | B168: 2109 | C168: 47.23724 | D168: 626.92435 | E168: 10833.188 | F168: 580.43886 | G168: 410.17741 | H168: 509.96821 | I168: 670.21696 | J168: Measure 8 | K168: Country
A169: Grand Total | B169: 2491 | C169: 47.23724 | D169: 697.03281 | E169: 10833.188 | F169: 682.86754 | G169: #NUM! | H169: #NUM! | I169: #NUM! | J169: #NUM! | K169: Country
A301: ALBERTA CANADA | B301: 8 | C301: 55.468529 | D301: 581.71911 | E301: 1294.774 | F301: 381.88494 | G301: 390.02856 | H301: 487.40224 | I301: 867.01014 | J301: Measure 8 | K301: Region
A302: JAVA ISLAND INDONESIA | B302: 8 | C302: 552.38113 | D302: 1888.2398 | E302: 3356.0358 | F302: 940.51433 | G302: 1125.4183 | H302: 1768.0829 | I302: 2781.0234 | J302: Measure 8 | K302: Region
A303: MAHARASHTRA INDIA | B303: 9 | C303: 298.64218 | D303: 1234.7453 | E303: 2232.8427 | F303: 667.10202 | G303: 646.6758 | H303: 1151.8022 | I303: 1841.9661 | J303: Measure 8 | K303: Region
A304: GUANGDONG CHINA | B304: 9 | C304: 1065.7135 | D304: 1971.4771 | E304: 3740.69 | F304: 733.07775 | G304: 1626.4641 | H304: 1888.9316 | I304: 2068.6076 | J304: Measure 8 | K304: Region
A305: BANGKOK 200KM | B305: 10 | C305: 662.21712 | D305: 1512.1654 | E305: 2384.9265 | F305: 587.11176 | G305: 1021.4106 | H305: 1433.2605 | I305: 2036.7678 | J305: Measure 8 | K305: Region
A306: SOUTHERN GERMANY | B306: 10 | C306: 190.09324 | D306: 413.20258 | E306: 965.84317 | F306: 239.09464 | G306: 232.50395 | H306: 326.14556 | I306: 535.24574 | J306: Measure 8 | K306: Region
A307: NORTHERN GERMANY | B307: 13 | C307: 180.92428 | D307: 494.07654 | E307: 750.85102 | F307: 192.40257 | G307: 305.12723 | H307: 524.28442 | I307: 640.26551 | J307: Measure 8 | K307: Region
A308: Toronto 200KM | B308: 17 | C308: 81.470052 | D308: 583.00045 | E308: 1169.9997 | F308: 261.20359 | G308: 414.01778 | H308: 546.17642 | I308: 681.41643 | J308: Measure 8 | K308: Region
A309: CARIBBEAN | B309: 28 | C309: 365.39322 | D309: 1434.4768 | E309: 4827.0727 | F309: 962.64083 | G309: 828.42458 | H309: 1179.9646 | I309: 1804.5286 | J309: Measure 8 | K309: Region
A310: N/A | B310: 2503 | C310: 47.23724 | D310: 714.97306 | E310: 11707.538 | F310: 773.3003 | G310: 413.88116 | H310: 527.08268 | I310: 730.10819 | J310: Measure 8 | K310: Region
A311: Grand Total | B311: 2615 | C311: 47.23724 | D311: 731.91062 | E311: 11707.538 | F311: 780.19699 | G311: #NUM! | H311: #NUM! | I311: #NUM! | J311: #NUM! | K311: Region
...

Sheet ImpM9
A1: Row Labels | B1: Count | C1: Min | D1: Mean | E1: Max | F1: SD | G1: 25th | H1: Median | I1: 75th | J1: Measure | K1: Geography
A2: SAO PAULO | B2: 8 | C2: 515.58884 | D2: 2557.8204 | E2: 5379.2952 | F2: 1864.4654 | G2: 1146.4531 | H2: 1689.6728 | I2: 4676.8406 | J2: Measure 9 | K2: MSA
A3: Las Vegas-Henderson-Paradise, NV | B3: 8 | C3: 1790.0668 | D3: 2975.6711 | E3: 3996.0104 | F3: 738.93764 | G3: 2295.6212 | H3: 3002.2263 | I3: 3541.863 | J3: Measure 9 | K3: MSA
A4: Savannah, GA | B4: 8 | C4: 1317.2292 | D4: 2135.6319 | E4: 3113.1292 | F4: 579.18647 | G4: 1668.8326 | H4: 2050.2206 | I4: 2602.9942 | J4: Measure 9 | K4: MSA
A5: PARIS | B5: 8 | C5: 2081.6292 | D5: 3062.3592 | E5: 3769.1154 | F5: 526.61122 | G5: 2737.0462 | H5: 3125.0722 | I5: 3479.2914 | J5: Measure 9 | K5: MSA
A6: JAVA ISLAND INDONESIA | B6: 8 | C6: 1246.3478 | D6: 3598.4252 | E6: 7745.5621 | F6: 1971.6902 | G6: 2167.8795 | H6: 3357.918 | I6: 4357.125 | J6: Measure 9 | K6: MSA
A7: TORONTO | B7: 9 | C7: 1699.6379 | D7: 2390.3454 | E7: 4070.2594 | F7: 709.8194 | G7: 1851.9042 | H7: 2316.429 | I7: 2539.9081 | J7: Measure 9 | K7: MSA
A8: Albuquerque, NM | B8: 9 | C8: 1855.4405 | D8: 2457.9693 | E8: 3113.4165 | F8: 472.39219 | G8: 1925.2464 | H8: 2592.4294 | I8: 2885.686 | J8: Measure 9 | K8: MSA
